2023-04-04 11:50:56 INFO Retry attempt failed:
Traceback (most recent call last):
  File "D:\anaconda3\envs\STAR_DEPLOY\lib\site-packages\urllib3\connectionpool.py", line 700, in urlopen
    self._prepare_proxy(conn)
  File "D:\anaconda3\envs\STAR_DEPLOY\lib\site-packages\urllib3\connectionpool.py", line 996, in _prepare_proxy
    conn.connect()
  File "D:\anaconda3\envs\STAR_DEPLOY\lib\site-packages\urllib3\connection.py", line 364, in connect
    self.sock = conn = self._connect_tls_proxy(hostname, conn)
  File "D:\anaconda3\envs\STAR_DEPLOY\lib\site-packages\urllib3\connection.py", line 499, in _connect_tls_proxy
    socket = ssl_wrap_socket(
  File "D:\anaconda3\envs\STAR_DEPLOY\lib\site-packages\urllib3\util\ssl_.py", line 453, in ssl_wrap_socket
    ssl_sock = _ssl_wrap_socket_impl(sock, context, tls_in_tls)
  File "D:\anaconda3\envs\STAR_DEPLOY\lib\site-packages\urllib3\util\ssl_.py", line 495, in _ssl_wrap_socket_impl
    return ssl_context.wrap_socket(sock)
  File "D:\anaconda3\envs\STAR_DEPLOY\lib\ssl.py", line 500, in wrap_socket
    return self.sslsocket_class._create(
  File "D:\anaconda3\envs\STAR_DEPLOY\lib\ssl.py", line 1040, in _create
    self.do_handshake()
  File "D:\anaconda3\envs\STAR_DEPLOY\lib\ssl.py", line 1309, in do_handshake
    self._sslobj.do_handshake()
ssl.SSLEOFError: EOF occurred in violation of protocol (_ssl.c:1131)

During handling of the above exception, another exception occurred:

Traceback (most recent call last):
  File "D:\anaconda3\envs\STAR_DEPLOY\lib\site-packages\requests\adapters.py", line 489, in send
    resp = conn.urlopen(
  File "D:\anaconda3\envs\STAR_DEPLOY\lib\site-packages\urllib3\connectionpool.py", line 787, in urlopen
    retries = retries.increment(
  File "D:\anaconda3\envs\STAR_DEPLOY\lib\site-packages\urllib3\util\retry.py", line 592, in increment
    raise MaxRetryError(_pool, url, error or ResponseError(cause))
urllib3.exceptions.MaxRetryError: HTTPSConnectionPool(host='api.wandb.ai', port=443): Max retries exceeded with url: /graphql (Caused by SSLError(SSLEOFError(8, 'EOF occurred in violation of protocol (_ssl.c:1131)')))

During handling of the above exception, another exception occurred:

Traceback (most recent call last):
  File "D:\anaconda3\envs\STAR_DEPLOY\lib\site-packages\wandb\sdk\lib\retry.py", line 131, in __call__
    result = self._call_fn(*args, **kwargs)
  File "D:\anaconda3\envs\STAR_DEPLOY\lib\site-packages\wandb\sdk\internal\internal_api.py", line 243, in execute
    return self.client.execute(*args, **kwargs)  # type: ignore
  File "D:\anaconda3\envs\STAR_DEPLOY\lib\site-packages\wandb\vendor\gql-0.2.0\wandb_gql\client.py", line 52, in execute
    result = self._get_result(document, *args, **kwargs)
  File "D:\anaconda3\envs\STAR_DEPLOY\lib\site-packages\wandb\vendor\gql-0.2.0\wandb_gql\client.py", line 60, in _get_result
    return self.transport.execute(document, *args, **kwargs)
  File "D:\anaconda3\envs\STAR_DEPLOY\lib\site-packages\wandb\vendor\gql-0.2.0\wandb_gql\transport\requests.py", line 38, in execute
    request = requests.post(self.url, **post_args)
  File "D:\anaconda3\envs\STAR_DEPLOY\lib\site-packages\requests\api.py", line 115, in post
    return request("post", url, data=data, json=json, **kwargs)
  File "D:\anaconda3\envs\STAR_DEPLOY\lib\site-packages\requests\api.py", line 59, in request
    return session.request(method=method, url=url, **kwargs)
  File "D:\anaconda3\envs\STAR_DEPLOY\lib\site-packages\requests\sessions.py", line 587, in request
    resp = self.send(prep, **send_kwargs)
  File "D:\anaconda3\envs\STAR_DEPLOY\lib\site-packages\requests\sessions.py", line 701, in send
    r = adapter.send(request, **kwargs)
  File "D:\anaconda3\envs\STAR_DEPLOY\lib\site-packages\requests\adapters.py", line 563, in send
    raise SSLError(e, request=request)
requests.exceptions.SSLError: HTTPSConnectionPool(host='api.wandb.ai', port=443): Max retries exceeded with url: /graphql (Caused by SSLError(SSLEOFError(8, 'EOF occurred in violation of protocol (_ssl.c:1131)')))
2023-04-04 19:30:52 WARNING Retrying (Retry(total=2, connect=None, read=None, redirect=None, status=None)) after connection broken by 'SSLError(SSLEOFError(8, 'EOF occurred in violation of protocol (_ssl.c:1131)'))': /api/5288891/envelope/
2023-04-04 19:30:52 WARNING Retrying (Retry(total=1, connect=None, read=None, redirect=None, status=None)) after connection broken by 'SSLError(SSLEOFError(8, 'EOF occurred in violation of protocol (_ssl.c:1131)'))': /api/5288891/envelope/
2023-04-04 19:30:52 WARNING Retrying (Retry(total=0, connect=None, read=None, redirect=None, status=None)) after connection broken by 'SSLError(SSLEOFError(8, 'EOF occurred in violation of protocol (_ssl.c:1131)'))': /api/5288891/envelope/
2023-04-04 20:08:57 WARNING Retrying (Retry(total=2, connect=None, read=None, redirect=None, status=None)) after connection broken by 'SSLError(SSLEOFError(8, 'EOF occurred in violation of protocol (_ssl.c:1131)'))': /api/5288891/envelope/
2023-04-04 20:08:57 WARNING Retrying (Retry(total=1, connect=None, read=None, redirect=None, status=None)) after connection broken by 'SSLError(SSLEOFError(8, 'EOF occurred in violation of protocol (_ssl.c:1131)'))': /api/5288891/envelope/
2023-04-04 20:08:57 WARNING Retrying (Retry(total=0, connect=None, read=None, redirect=None, status=None)) after connection broken by 'SSLError(SSLEOFError(8, 'EOF occurred in violation of protocol (_ssl.c:1131)'))': /api/5288891/envelope/
2023-04-04 20:15:50 WARNING Retrying (Retry(total=2, connect=None, read=None, redirect=None, status=None)) after connection broken by 'SSLError(SSLEOFError(8, 'EOF occurred in violation of protocol (_ssl.c:1131)'))': /api/5288891/envelope/
2023-04-04 20:15:50 WARNING Retrying (Retry(total=1, connect=None, read=None, redirect=None, status=None)) after connection broken by 'SSLError(SSLEOFError(8, 'EOF occurred in violation of protocol (_ssl.c:1131)'))': /api/5288891/envelope/
2023-04-04 20:15:50 WARNING Retrying (Retry(total=0, connect=None, read=None, redirect=None, status=None)) after connection broken by 'SSLError(SSLEOFError(8, 'EOF occurred in violation of protocol (_ssl.c:1131)'))': /api/5288891/envelope/
2023-04-04 20:24:03 WARNING Retrying (Retry(total=2, connect=None, read=None, redirect=None, status=None)) after connection broken by 'SSLError(SSLEOFError(8, 'EOF occurred in violation of protocol (_ssl.c:1131)'))': /api/5288891/envelope/
2023-04-04 20:24:03 WARNING Retrying (Retry(total=1, connect=None, read=None, redirect=None, status=None)) after connection broken by 'SSLError(SSLEOFError(8, 'EOF occurred in violation of protocol (_ssl.c:1131)'))': /api/5288891/envelope/
2023-04-04 20:24:03 WARNING Retrying (Retry(total=0, connect=None, read=None, redirect=None, status=None)) after connection broken by 'SSLError(SSLEOFError(8, 'EOF occurred in violation of protocol (_ssl.c:1131)'))': /api/5288891/envelope/
2023-04-04 20:31:30 WARNING Retrying (Retry(total=2, connect=None, read=None, redirect=None, status=None)) after connection broken by 'SSLError(SSLEOFError(8, 'EOF occurred in violation of protocol (_ssl.c:1131)'))': /api/5288891/envelope/
2023-04-04 20:31:30 WARNING Retrying (Retry(total=1, connect=None, read=None, redirect=None, status=None)) after connection broken by 'SSLError(SSLEOFError(8, 'EOF occurred in violation of protocol (_ssl.c:1131)'))': /api/5288891/envelope/
2023-04-04 20:31:30 WARNING Retrying (Retry(total=0, connect=None, read=None, redirect=None, status=None)) after connection broken by 'SSLError(SSLEOFError(8, 'EOF occurred in violation of protocol (_ssl.c:1131)'))': /api/5288891/envelope/
2023-04-05 15:35:45 INFO open for scan: D:\PycharmProjects\PPOimplementation\wandb\offline-run-20230404_203023-xcytp9ss\run-xcytp9ss.wandb
2023-04-05 15:36:33 INFO Retry attempt failed:
Traceback (most recent call last):
  File "D:\anaconda3\envs\STAR_DEPLOY\lib\site-packages\urllib3\connectionpool.py", line 449, in _make_request
    six.raise_from(e, None)
  File "<string>", line 3, in raise_from
  File "D:\anaconda3\envs\STAR_DEPLOY\lib\site-packages\urllib3\connectionpool.py", line 444, in _make_request
    httplib_response = conn.getresponse()
  File "D:\anaconda3\envs\STAR_DEPLOY\lib\http\client.py", line 1348, in getresponse
    response.begin()
  File "D:\anaconda3\envs\STAR_DEPLOY\lib\http\client.py", line 316, in begin
    version, status, reason = self._read_status()
  File "D:\anaconda3\envs\STAR_DEPLOY\lib\http\client.py", line 277, in _read_status
    line = str(self.fp.readline(_MAXLINE + 1), "iso-8859-1")
  File "D:\anaconda3\envs\STAR_DEPLOY\lib\socket.py", line 669, in readinto
    return self._sock.recv_into(b)
  File "D:\anaconda3\envs\STAR_DEPLOY\lib\ssl.py", line 1241, in recv_into
    return self.read(nbytes, buffer)
  File "D:\anaconda3\envs\STAR_DEPLOY\lib\ssl.py", line 1099, in read
    return self._sslobj.read(len, buffer)
socket.timeout: The read operation timed out

During handling of the above exception, another exception occurred:

Traceback (most recent call last):
  File "D:\anaconda3\envs\STAR_DEPLOY\lib\site-packages\requests\adapters.py", line 489, in send
    resp = conn.urlopen(
  File "D:\anaconda3\envs\STAR_DEPLOY\lib\site-packages\urllib3\connectionpool.py", line 787, in urlopen
    retries = retries.increment(
  File "D:\anaconda3\envs\STAR_DEPLOY\lib\site-packages\urllib3\util\retry.py", line 550, in increment
    raise six.reraise(type(error), error, _stacktrace)
  File "D:\anaconda3\envs\STAR_DEPLOY\lib\site-packages\urllib3\packages\six.py", line 770, in reraise
    raise value
  File "D:\anaconda3\envs\STAR_DEPLOY\lib\site-packages\urllib3\connectionpool.py", line 703, in urlopen
    httplib_response = self._make_request(
  File "D:\anaconda3\envs\STAR_DEPLOY\lib\site-packages\urllib3\connectionpool.py", line 451, in _make_request
    self._raise_timeout(err=e, url=url, timeout_value=read_timeout)
  File "D:\anaconda3\envs\STAR_DEPLOY\lib\site-packages\urllib3\connectionpool.py", line 340, in _raise_timeout
    raise ReadTimeoutError(
urllib3.exceptions.ReadTimeoutError: HTTPSConnectionPool(host='api.wandb.ai', port=443): Read timed out. (read timeout=10)

During handling of the above exception, another exception occurred:

Traceback (most recent call last):
  File "D:\anaconda3\envs\STAR_DEPLOY\lib\site-packages\wandb\sdk\lib\retry.py", line 131, in __call__
    result = self._call_fn(*args, **kwargs)
  File "D:\anaconda3\envs\STAR_DEPLOY\lib\site-packages\wandb\sdk\internal\internal_api.py", line 243, in execute
    return self.client.execute(*args, **kwargs)  # type: ignore
  File "D:\anaconda3\envs\STAR_DEPLOY\lib\site-packages\wandb\vendor\gql-0.2.0\wandb_gql\client.py", line 52, in execute
    result = self._get_result(document, *args, **kwargs)
  File "D:\anaconda3\envs\STAR_DEPLOY\lib\site-packages\wandb\vendor\gql-0.2.0\wandb_gql\client.py", line 60, in _get_result
    return self.transport.execute(document, *args, **kwargs)
  File "D:\anaconda3\envs\STAR_DEPLOY\lib\site-packages\wandb\vendor\gql-0.2.0\wandb_gql\transport\requests.py", line 38, in execute
    request = requests.post(self.url, **post_args)
  File "D:\anaconda3\envs\STAR_DEPLOY\lib\site-packages\requests\api.py", line 115, in post
    return request("post", url, data=data, json=json, **kwargs)
  File "D:\anaconda3\envs\STAR_DEPLOY\lib\site-packages\requests\api.py", line 59, in request
    return session.request(method=method, url=url, **kwargs)
  File "D:\anaconda3\envs\STAR_DEPLOY\lib\site-packages\requests\sessions.py", line 587, in request
    resp = self.send(prep, **send_kwargs)
  File "D:\anaconda3\envs\STAR_DEPLOY\lib\site-packages\requests\sessions.py", line 701, in send
    r = adapter.send(request, **kwargs)
  File "D:\anaconda3\envs\STAR_DEPLOY\lib\site-packages\requests\adapters.py", line 578, in send
    raise ReadTimeout(e, request=request)
requests.exceptions.ReadTimeout: HTTPSConnectionPool(host='api.wandb.ai', port=443): Read timed out. (read timeout=10)
2023-04-05 15:53:33 INFO open for scan: D:\PycharmProjects\PPOimplementation\wandb\offline-run-20230404_203023-xcytp9ss\run-xcytp9ss.wandb
2023-04-05 15:54:08 INFO Retry attempt failed:
Traceback (most recent call last):
  File "D:\anaconda3\envs\STAR_DEPLOY\lib\site-packages\urllib3\connectionpool.py", line 449, in _make_request
    six.raise_from(e, None)
  File "<string>", line 3, in raise_from
  File "D:\anaconda3\envs\STAR_DEPLOY\lib\site-packages\urllib3\connectionpool.py", line 444, in _make_request
    httplib_response = conn.getresponse()
  File "D:\anaconda3\envs\STAR_DEPLOY\lib\http\client.py", line 1348, in getresponse
    response.begin()
  File "D:\anaconda3\envs\STAR_DEPLOY\lib\http\client.py", line 316, in begin
    version, status, reason = self._read_status()
  File "D:\anaconda3\envs\STAR_DEPLOY\lib\http\client.py", line 277, in _read_status
    line = str(self.fp.readline(_MAXLINE + 1), "iso-8859-1")
  File "D:\anaconda3\envs\STAR_DEPLOY\lib\socket.py", line 669, in readinto
    return self._sock.recv_into(b)
  File "D:\anaconda3\envs\STAR_DEPLOY\lib\ssl.py", line 1241, in recv_into
    return self.read(nbytes, buffer)
  File "D:\anaconda3\envs\STAR_DEPLOY\lib\ssl.py", line 1099, in read
    return self._sslobj.read(len, buffer)
socket.timeout: The read operation timed out

During handling of the above exception, another exception occurred:

Traceback (most recent call last):
  File "D:\anaconda3\envs\STAR_DEPLOY\lib\site-packages\requests\adapters.py", line 489, in send
    resp = conn.urlopen(
  File "D:\anaconda3\envs\STAR_DEPLOY\lib\site-packages\urllib3\connectionpool.py", line 787, in urlopen
    retries = retries.increment(
  File "D:\anaconda3\envs\STAR_DEPLOY\lib\site-packages\urllib3\util\retry.py", line 550, in increment
    raise six.reraise(type(error), error, _stacktrace)
  File "D:\anaconda3\envs\STAR_DEPLOY\lib\site-packages\urllib3\packages\six.py", line 770, in reraise
    raise value
  File "D:\anaconda3\envs\STAR_DEPLOY\lib\site-packages\urllib3\connectionpool.py", line 703, in urlopen
    httplib_response = self._make_request(
  File "D:\anaconda3\envs\STAR_DEPLOY\lib\site-packages\urllib3\connectionpool.py", line 451, in _make_request
    self._raise_timeout(err=e, url=url, timeout_value=read_timeout)
  File "D:\anaconda3\envs\STAR_DEPLOY\lib\site-packages\urllib3\connectionpool.py", line 340, in _raise_timeout
    raise ReadTimeoutError(
urllib3.exceptions.ReadTimeoutError: HTTPSConnectionPool(host='api.wandb.ai', port=443): Read timed out. (read timeout=10)

During handling of the above exception, another exception occurred:

Traceback (most recent call last):
  File "D:\anaconda3\envs\STAR_DEPLOY\lib\site-packages\wandb\sdk\lib\retry.py", line 131, in __call__
    result = self._call_fn(*args, **kwargs)
  File "D:\anaconda3\envs\STAR_DEPLOY\lib\site-packages\wandb\sdk\internal\internal_api.py", line 243, in execute
    return self.client.execute(*args, **kwargs)  # type: ignore
  File "D:\anaconda3\envs\STAR_DEPLOY\lib\site-packages\wandb\vendor\gql-0.2.0\wandb_gql\client.py", line 52, in execute
    result = self._get_result(document, *args, **kwargs)
  File "D:\anaconda3\envs\STAR_DEPLOY\lib\site-packages\wandb\vendor\gql-0.2.0\wandb_gql\client.py", line 60, in _get_result
    return self.transport.execute(document, *args, **kwargs)
  File "D:\anaconda3\envs\STAR_DEPLOY\lib\site-packages\wandb\vendor\gql-0.2.0\wandb_gql\transport\requests.py", line 38, in execute
    request = requests.post(self.url, **post_args)
  File "D:\anaconda3\envs\STAR_DEPLOY\lib\site-packages\requests\api.py", line 115, in post
    return request("post", url, data=data, json=json, **kwargs)
  File "D:\anaconda3\envs\STAR_DEPLOY\lib\site-packages\requests\api.py", line 59, in request
    return session.request(method=method, url=url, **kwargs)
  File "D:\anaconda3\envs\STAR_DEPLOY\lib\site-packages\requests\sessions.py", line 587, in request
    resp = self.send(prep, **send_kwargs)
  File "D:\anaconda3\envs\STAR_DEPLOY\lib\site-packages\requests\sessions.py", line 701, in send
    r = adapter.send(request, **kwargs)
  File "D:\anaconda3\envs\STAR_DEPLOY\lib\site-packages\requests\adapters.py", line 578, in send
    raise ReadTimeout(e, request=request)
requests.exceptions.ReadTimeout: HTTPSConnectionPool(host='api.wandb.ai', port=443): Read timed out. (read timeout=10)
2023-04-05 15:55:40 INFO open for scan: D:\PycharmProjects\PPOimplementation\wandb\offline-run-20230404_203023-xcytp9ss\run-xcytp9ss.wandb
2023-04-05 15:55:43 INFO Retry attempt failed:
Traceback (most recent call last):
  File "D:\anaconda3\envs\STAR_DEPLOY\lib\site-packages\urllib3\connectionpool.py", line 700, in urlopen
    self._prepare_proxy(conn)
  File "D:\anaconda3\envs\STAR_DEPLOY\lib\site-packages\urllib3\connectionpool.py", line 996, in _prepare_proxy
    conn.connect()
  File "D:\anaconda3\envs\STAR_DEPLOY\lib\site-packages\urllib3\connection.py", line 364, in connect
    self.sock = conn = self._connect_tls_proxy(hostname, conn)
  File "D:\anaconda3\envs\STAR_DEPLOY\lib\site-packages\urllib3\connection.py", line 499, in _connect_tls_proxy
    socket = ssl_wrap_socket(
  File "D:\anaconda3\envs\STAR_DEPLOY\lib\site-packages\urllib3\util\ssl_.py", line 453, in ssl_wrap_socket
    ssl_sock = _ssl_wrap_socket_impl(sock, context, tls_in_tls)
  File "D:\anaconda3\envs\STAR_DEPLOY\lib\site-packages\urllib3\util\ssl_.py", line 495, in _ssl_wrap_socket_impl
    return ssl_context.wrap_socket(sock)
  File "D:\anaconda3\envs\STAR_DEPLOY\lib\ssl.py", line 500, in wrap_socket
    return self.sslsocket_class._create(
  File "D:\anaconda3\envs\STAR_DEPLOY\lib\ssl.py", line 1040, in _create
    self.do_handshake()
  File "D:\anaconda3\envs\STAR_DEPLOY\lib\ssl.py", line 1309, in do_handshake
    self._sslobj.do_handshake()
ssl.SSLEOFError: EOF occurred in violation of protocol (_ssl.c:1131)

During handling of the above exception, another exception occurred:

Traceback (most recent call last):
  File "D:\anaconda3\envs\STAR_DEPLOY\lib\site-packages\requests\adapters.py", line 489, in send
    resp = conn.urlopen(
  File "D:\anaconda3\envs\STAR_DEPLOY\lib\site-packages\urllib3\connectionpool.py", line 787, in urlopen
    retries = retries.increment(
  File "D:\anaconda3\envs\STAR_DEPLOY\lib\site-packages\urllib3\util\retry.py", line 592, in increment
    raise MaxRetryError(_pool, url, error or ResponseError(cause))
urllib3.exceptions.MaxRetryError: HTTPSConnectionPool(host='api.wandb.ai', port=443): Max retries exceeded with url: /graphql (Caused by SSLError(SSLEOFError(8, 'EOF occurred in violation of protocol (_ssl.c:1131)')))

During handling of the above exception, another exception occurred:

Traceback (most recent call last):
  File "D:\anaconda3\envs\STAR_DEPLOY\lib\site-packages\wandb\sdk\lib\retry.py", line 131, in __call__
    result = self._call_fn(*args, **kwargs)
  File "D:\anaconda3\envs\STAR_DEPLOY\lib\site-packages\wandb\sdk\internal\internal_api.py", line 243, in execute
    return self.client.execute(*args, **kwargs)  # type: ignore
  File "D:\anaconda3\envs\STAR_DEPLOY\lib\site-packages\wandb\vendor\gql-0.2.0\wandb_gql\client.py", line 52, in execute
    result = self._get_result(document, *args, **kwargs)
  File "D:\anaconda3\envs\STAR_DEPLOY\lib\site-packages\wandb\vendor\gql-0.2.0\wandb_gql\client.py", line 60, in _get_result
    return self.transport.execute(document, *args, **kwargs)
  File "D:\anaconda3\envs\STAR_DEPLOY\lib\site-packages\wandb\vendor\gql-0.2.0\wandb_gql\transport\requests.py", line 38, in execute
    request = requests.post(self.url, **post_args)
  File "D:\anaconda3\envs\STAR_DEPLOY\lib\site-packages\requests\api.py", line 115, in post
    return request("post", url, data=data, json=json, **kwargs)
  File "D:\anaconda3\envs\STAR_DEPLOY\lib\site-packages\requests\api.py", line 59, in request
    return session.request(method=method, url=url, **kwargs)
  File "D:\anaconda3\envs\STAR_DEPLOY\lib\site-packages\requests\sessions.py", line 587, in request
    resp = self.send(prep, **send_kwargs)
  File "D:\anaconda3\envs\STAR_DEPLOY\lib\site-packages\requests\sessions.py", line 701, in send
    r = adapter.send(request, **kwargs)
  File "D:\anaconda3\envs\STAR_DEPLOY\lib\site-packages\requests\adapters.py", line 563, in send
    raise SSLError(e, request=request)
requests.exceptions.SSLError: HTTPSConnectionPool(host='api.wandb.ai', port=443): Max retries exceeded with url: /graphql (Caused by SSLError(SSLEOFError(8, 'EOF occurred in violation of protocol (_ssl.c:1131)')))
2023-04-05 16:05:46 INFO open for scan: D:\PycharmProjects\PPOimplementation\wandb\offline-run-20230404_203023-xcytp9ss\run-xcytp9ss.wandb
2023-04-05 16:06:20 INFO Retry attempt failed:
Traceback (most recent call last):
  File "D:\anaconda3\envs\STAR_DEPLOY\lib\site-packages\urllib3\connectionpool.py", line 449, in _make_request
    six.raise_from(e, None)
  File "<string>", line 3, in raise_from
  File "D:\anaconda3\envs\STAR_DEPLOY\lib\site-packages\urllib3\connectionpool.py", line 444, in _make_request
    httplib_response = conn.getresponse()
  File "D:\anaconda3\envs\STAR_DEPLOY\lib\http\client.py", line 1348, in getresponse
    response.begin()
  File "D:\anaconda3\envs\STAR_DEPLOY\lib\http\client.py", line 316, in begin
    version, status, reason = self._read_status()
  File "D:\anaconda3\envs\STAR_DEPLOY\lib\http\client.py", line 277, in _read_status
    line = str(self.fp.readline(_MAXLINE + 1), "iso-8859-1")
  File "D:\anaconda3\envs\STAR_DEPLOY\lib\socket.py", line 669, in readinto
    return self._sock.recv_into(b)
  File "D:\anaconda3\envs\STAR_DEPLOY\lib\ssl.py", line 1241, in recv_into
    return self.read(nbytes, buffer)
  File "D:\anaconda3\envs\STAR_DEPLOY\lib\ssl.py", line 1099, in read
    return self._sslobj.read(len, buffer)
socket.timeout: The read operation timed out

During handling of the above exception, another exception occurred:

Traceback (most recent call last):
  File "D:\anaconda3\envs\STAR_DEPLOY\lib\site-packages\requests\adapters.py", line 489, in send
    resp = conn.urlopen(
  File "D:\anaconda3\envs\STAR_DEPLOY\lib\site-packages\urllib3\connectionpool.py", line 787, in urlopen
    retries = retries.increment(
  File "D:\anaconda3\envs\STAR_DEPLOY\lib\site-packages\urllib3\util\retry.py", line 550, in increment
    raise six.reraise(type(error), error, _stacktrace)
  File "D:\anaconda3\envs\STAR_DEPLOY\lib\site-packages\urllib3\packages\six.py", line 770, in reraise
    raise value
  File "D:\anaconda3\envs\STAR_DEPLOY\lib\site-packages\urllib3\connectionpool.py", line 703, in urlopen
    httplib_response = self._make_request(
  File "D:\anaconda3\envs\STAR_DEPLOY\lib\site-packages\urllib3\connectionpool.py", line 451, in _make_request
    self._raise_timeout(err=e, url=url, timeout_value=read_timeout)
  File "D:\anaconda3\envs\STAR_DEPLOY\lib\site-packages\urllib3\connectionpool.py", line 340, in _raise_timeout
    raise ReadTimeoutError(
urllib3.exceptions.ReadTimeoutError: HTTPSConnectionPool(host='api.wandb.ai', port=443): Read timed out. (read timeout=10)

During handling of the above exception, another exception occurred:

Traceback (most recent call last):
  File "D:\anaconda3\envs\STAR_DEPLOY\lib\site-packages\wandb\sdk\lib\retry.py", line 131, in __call__
    result = self._call_fn(*args, **kwargs)
  File "D:\anaconda3\envs\STAR_DEPLOY\lib\site-packages\wandb\sdk\internal\internal_api.py", line 243, in execute
    return self.client.execute(*args, **kwargs)  # type: ignore
  File "D:\anaconda3\envs\STAR_DEPLOY\lib\site-packages\wandb\vendor\gql-0.2.0\wandb_gql\client.py", line 52, in execute
    result = self._get_result(document, *args, **kwargs)
  File "D:\anaconda3\envs\STAR_DEPLOY\lib\site-packages\wandb\vendor\gql-0.2.0\wandb_gql\client.py", line 60, in _get_result
    return self.transport.execute(document, *args, **kwargs)
  File "D:\anaconda3\envs\STAR_DEPLOY\lib\site-packages\wandb\vendor\gql-0.2.0\wandb_gql\transport\requests.py", line 38, in execute
    request = requests.post(self.url, **post_args)
  File "D:\anaconda3\envs\STAR_DEPLOY\lib\site-packages\requests\api.py", line 115, in post
    return request("post", url, data=data, json=json, **kwargs)
  File "D:\anaconda3\envs\STAR_DEPLOY\lib\site-packages\requests\api.py", line 59, in request
    return session.request(method=method, url=url, **kwargs)
  File "D:\anaconda3\envs\STAR_DEPLOY\lib\site-packages\requests\sessions.py", line 587, in request
    resp = self.send(prep, **send_kwargs)
  File "D:\anaconda3\envs\STAR_DEPLOY\lib\site-packages\requests\sessions.py", line 701, in send
    r = adapter.send(request, **kwargs)
  File "D:\anaconda3\envs\STAR_DEPLOY\lib\site-packages\requests\adapters.py", line 578, in send
    raise ReadTimeout(e, request=request)
requests.exceptions.ReadTimeout: HTTPSConnectionPool(host='api.wandb.ai', port=443): Read timed out. (read timeout=10)
2023-04-06 10:30:08 INFO open for scan: D:\PycharmProjects\PPOimplementation\wandb\offline-run-20230405_161533-9enh1si8\run-9enh1si8.wandb
2023-04-06 10:30:09 INFO watching files in: D:\PycharmProjects\PPOimplementation\wandb\offline-run-20230405_161533-9enh1si8\files
2023-04-06 10:30:09 INFO run started: 9enh1si8 with start time 1680682533.77877
2023-04-06 10:30:09 INFO saving file wandb-metadata.json with policy now
2023-04-06 10:30:09 INFO saving file code\ppo_continuous_action.py with policy now
2023-04-06 10:30:09 INFO saving file diff.patch with policy now
2023-04-06 10:30:11 INFO saving file wandb-summary.json with policy end
2023-04-06 10:30:11 INFO handling exit code: 0
2023-04-06 10:30:11 INFO handling runtime: 3829
2023-04-06 10:30:11 INFO saving file wandb-summary.json with policy end
2023-04-06 10:30:11 INFO send defer
2023-04-06 10:30:11 INFO handle sender defer: 0
2023-04-06 10:30:11 INFO send defer: 1
2023-04-06 10:30:11 INFO handle sender defer: 1
2023-04-06 10:30:11 INFO send defer: 2
2023-04-06 10:30:11 INFO handle sender defer: 2
2023-04-06 10:30:11 INFO send defer: 3
2023-04-06 10:30:11 INFO handle sender defer: 3
2023-04-06 10:30:11 INFO send defer: 4
2023-04-06 10:30:11 INFO handle sender defer: 4
2023-04-06 10:30:11 INFO send defer: 5
2023-04-06 10:30:11 INFO handle sender defer: 5
2023-04-06 10:30:11 INFO send defer: 6
2023-04-06 10:30:11 INFO handle sender defer: 6
2023-04-06 10:30:11 INFO file/dir modified: D:\PycharmProjects\PPOimplementation\wandb\offline-run-20230405_161533-9enh1si8\files\wandb-summary.json
2023-04-06 10:30:11 INFO file/dir created: D:\PycharmProjects\PPOimplementation\wandb\offline-run-20230405_161533-9enh1si8\files\output.log
2023-04-06 10:30:11 INFO Skipped uploading C:\Users\JinLab\AppData\Local\Temp\tmpwoi0jvw2wandb\3a64y4bm-code/ppo_continuous_action.py
2023-04-06 10:30:12 INFO file/dir modified: D:\PycharmProjects\PPOimplementation\wandb\offline-run-20230405_161533-9enh1si8\files\wandb-summary.json
2023-04-06 10:30:12 INFO file/dir modified: D:\PycharmProjects\PPOimplementation\wandb\offline-run-20230405_161533-9enh1si8\files\output.log
2023-04-06 10:30:13 INFO Uploaded file C:\Users\JinLab\AppData\Local\Temp\tmpwoi0jvw2wandb\harbmy3k-wandb-metadata.json
2023-04-06 10:30:13 INFO send defer: 7
2023-04-06 10:30:13 INFO handle sender defer: 7
2023-04-06 10:30:14 INFO file/dir modified: D:\PycharmProjects\PPOimplementation\wandb\offline-run-20230405_161533-9enh1si8\files\config.yaml
2023-04-06 10:30:16 INFO send defer: 8
2023-04-06 10:30:16 INFO handle sender defer: 8
2023-04-06 10:30:16 INFO file/dir modified: D:\PycharmProjects\PPOimplementation\wandb\offline-run-20230405_161533-9enh1si8\files\output.log
2023-04-06 10:30:16 INFO send defer: 9
2023-04-06 10:30:17 INFO Uploaded file C:\Users\JinLab\AppData\Local\Temp\tmpwoi0jvw2wandb\dg9q4d6r-diff.patch
2023-04-06 10:30:19 INFO Uploaded file C:\Users\JinLab\AppData\Local\wandb\wandb\artifacts\staging\tmpb___2vbr
2023-04-06 10:30:20 INFO Uploaded file C:\Users\JinLab\AppData\Local\wandb\wandb\artifacts\staging\tmpyex2ehy5
2023-04-06 10:30:20 INFO Uploaded file C:\Users\JinLab\AppData\Local\wandb\wandb\artifacts\staging\tmpa6ixhzgm
2023-04-06 10:30:26 INFO sent artifact job-https___github.com_Porthoos_PPOimplementation.git_ppo_continuous_action.py - {'id': 'QXJ0aWZhY3Q6NDE0OTUxMTc2', 'digest': 'e133fa450795f72b95099b92dae99711', 'state': 'PENDING', 'aliases': [], 'artifactSequence': {'id': 'QXJ0aWZhY3RDb2xsZWN0aW9uOjYwNzYzOTMz', 'latestArtifact': None}, 'version': 'latest'}
2023-04-06 10:30:26 INFO handle sender defer: 9
2023-04-06 10:30:26 INFO shutting down directory watcher
2023-04-06 10:30:26 INFO scan: D:\PycharmProjects\PPOimplementation\wandb\offline-run-20230405_161533-9enh1si8\files
2023-04-06 10:30:26 INFO scan save: D:\PycharmProjects\PPOimplementation\wandb\offline-run-20230405_161533-9enh1si8\files\conda-environment.yaml conda-environment.yaml
2023-04-06 10:30:26 INFO scan save: D:\PycharmProjects\PPOimplementation\wandb\offline-run-20230405_161533-9enh1si8\files\config.yaml config.yaml
2023-04-06 10:30:26 INFO scan save: D:\PycharmProjects\PPOimplementation\wandb\offline-run-20230405_161533-9enh1si8\files\diff.patch diff.patch
2023-04-06 10:30:26 INFO scan save: D:\PycharmProjects\PPOimplementation\wandb\offline-run-20230405_161533-9enh1si8\files\output.log output.log
2023-04-06 10:30:26 INFO scan save: D:\PycharmProjects\PPOimplementation\wandb\offline-run-20230405_161533-9enh1si8\files\requirements.txt requirements.txt
2023-04-06 10:30:26 INFO scan save: D:\PycharmProjects\PPOimplementation\wandb\offline-run-20230405_161533-9enh1si8\files\wandb-metadata.json wandb-metadata.json
2023-04-06 10:30:26 INFO scan save: D:\PycharmProjects\PPOimplementation\wandb\offline-run-20230405_161533-9enh1si8\files\wandb-summary.json wandb-summary.json
2023-04-06 10:30:26 INFO scan save: D:\PycharmProjects\PPOimplementation\wandb\offline-run-20230405_161533-9enh1si8\files\code\ppo_continuous_action.py code\ppo_continuous_action.py
2023-04-06 10:30:26 INFO send defer: 10
2023-04-06 10:30:26 INFO handle sender defer: 10
2023-04-06 10:30:26 INFO shutting down file pusher
2023-04-06 10:30:26 INFO shutting down sender
2023-04-06 10:30:26 INFO shutting down file pusher
2023-04-06 10:30:26 INFO waiting for file pusher
2023-04-06 10:30:27 INFO Uploaded file D:\PycharmProjects\PPOimplementation\wandb\offline-run-20230405_161533-9enh1si8\files\requirements.txt
2023-04-06 10:30:27 INFO Uploaded file D:\PycharmProjects\PPOimplementation\wandb\offline-run-20230405_161533-9enh1si8\files\config.yaml
2023-04-06 10:30:28 INFO Uploaded file D:\PycharmProjects\PPOimplementation\wandb\offline-run-20230405_161533-9enh1si8\files\conda-environment.yaml
2023-04-06 10:30:28 INFO Uploaded file D:\PycharmProjects\PPOimplementation\wandb\offline-run-20230405_161533-9enh1si8\files\wandb-summary.json
2023-04-06 10:30:28 INFO Uploaded file D:\PycharmProjects\PPOimplementation\wandb\offline-run-20230405_161533-9enh1si8\files\output.log
2023-04-06 10:30:28 INFO send defer: 11
2023-04-06 10:31:02 INFO open for scan: D:\PycharmProjects\PPOimplementation\wandb\offline-run-20230404_203023-xcytp9ss\run-xcytp9ss.wandb
2023-04-06 10:31:03 INFO watching files in: D:\PycharmProjects\PPOimplementation\wandb\offline-run-20230404_203023-xcytp9ss\files
2023-04-06 10:31:03 INFO run started: xcytp9ss with start time 1680611423.252972
2023-04-06 10:31:03 INFO saving file wandb-metadata.json with policy now
2023-04-06 10:31:03 INFO saving file code\PPOmain.py with policy now
2023-04-06 10:31:03 INFO saving file diff.patch with policy now
2023-04-06 10:31:03 INFO saving file wandb-summary.json with policy end
2023-04-06 10:31:03 INFO handling exit code: 1
2023-04-06 10:31:03 INFO handling runtime: 2816
2023-04-06 10:31:03 INFO saving file wandb-summary.json with policy end
2023-04-06 10:31:03 INFO send defer
2023-04-06 10:31:03 INFO handle sender defer: 0
2023-04-06 10:31:03 INFO send defer: 1
2023-04-06 10:31:03 INFO handle sender defer: 1
2023-04-06 10:31:03 INFO send defer: 2
2023-04-06 10:31:03 INFO handle sender defer: 2
2023-04-06 10:31:03 INFO send defer: 3
2023-04-06 10:31:03 INFO handle sender defer: 3
2023-04-06 10:31:03 INFO send defer: 4
2023-04-06 10:31:03 INFO handle sender defer: 4
2023-04-06 10:31:03 INFO send defer: 5
2023-04-06 10:31:03 INFO handle sender defer: 5
2023-04-06 10:31:03 INFO send defer: 6
2023-04-06 10:31:03 INFO handle sender defer: 6
2023-04-06 10:31:04 INFO Skipped uploading C:\Users\JinLab\AppData\Local\Temp\tmpc7nsmnt0wandb\n3e9v8gz-code/PPOmain.py
2023-04-06 10:31:04 INFO file/dir modified: D:\PycharmProjects\PPOimplementation\wandb\offline-run-20230404_203023-xcytp9ss\files\wandb-summary.json
2023-04-06 10:31:04 INFO file/dir created: D:\PycharmProjects\PPOimplementation\wandb\offline-run-20230404_203023-xcytp9ss\files\output.log
2023-04-06 10:31:05 INFO Uploaded file C:\Users\JinLab\AppData\Local\Temp\tmpc7nsmnt0wandb\b6vok2vk-wandb-metadata.json
2023-04-06 10:31:05 INFO file/dir modified: D:\PycharmProjects\PPOimplementation\wandb\offline-run-20230404_203023-xcytp9ss\files\output.log
2023-04-06 10:31:07 INFO Uploaded file C:\Users\JinLab\AppData\Local\Temp\tmpc7nsmnt0wandb\ig7xnuo8-diff.patch
2023-04-06 10:31:26 INFO send defer: 7
2023-04-06 10:31:26 INFO handle sender defer: 7
2023-04-06 10:31:26 INFO file/dir modified: D:\PycharmProjects\PPOimplementation\wandb\offline-run-20230404_203023-xcytp9ss\files\config.yaml
2023-04-06 10:31:27 INFO send defer: 8
2023-04-06 10:31:27 INFO handle sender defer: 8
2023-04-06 10:31:27 INFO send defer: 9
2023-04-06 10:31:27 INFO file/dir modified: D:\PycharmProjects\PPOimplementation\wandb\offline-run-20230404_203023-xcytp9ss\files\output.log
2023-04-06 10:31:32 INFO Skipped uploading C:\Users\JinLab\AppData\Local\wandb\wandb\artifacts\staging\tmps9epzmlo
2023-04-06 10:31:32 INFO Uploaded file C:\Users\JinLab\AppData\Local\wandb\wandb\artifacts\staging\tmp1e_uczkp
2023-04-06 10:31:33 INFO Uploaded file C:\Users\JinLab\AppData\Local\wandb\wandb\artifacts\staging\tmplx63xeez
2023-04-06 10:31:37 INFO sent artifact job-https___github.com_Porthoos_PPOimplementation.git_PPOmain.py - {'id': 'QXJ0aWZhY3Q6NDE0OTUxODk2', 'digest': '637ccaec546d34bd20d79416c7a96c55', 'state': 'PENDING', 'aliases': [], 'artifactSequence': {'id': 'QXJ0aWZhY3RDb2xsZWN0aW9uOjYwMTIzOTQ3', 'latestArtifact': {'id': 'QXJ0aWZhY3Q6NDEyNjg4NTI1', 'versionIndex': 1}}, 'version': 'latest'}
2023-04-06 10:31:37 INFO handle sender defer: 9
2023-04-06 10:31:37 INFO shutting down directory watcher
2023-04-06 10:31:37 INFO scan: D:\PycharmProjects\PPOimplementation\wandb\offline-run-20230404_203023-xcytp9ss\files
2023-04-06 10:31:37 INFO scan save: D:\PycharmProjects\PPOimplementation\wandb\offline-run-20230404_203023-xcytp9ss\files\conda-environment.yaml conda-environment.yaml
2023-04-06 10:31:37 INFO scan save: D:\PycharmProjects\PPOimplementation\wandb\offline-run-20230404_203023-xcytp9ss\files\config.yaml config.yaml
2023-04-06 10:31:37 INFO scan save: D:\PycharmProjects\PPOimplementation\wandb\offline-run-20230404_203023-xcytp9ss\files\diff.patch diff.patch
2023-04-06 10:31:37 INFO scan save: D:\PycharmProjects\PPOimplementation\wandb\offline-run-20230404_203023-xcytp9ss\files\output.log output.log
2023-04-06 10:31:37 INFO scan save: D:\PycharmProjects\PPOimplementation\wandb\offline-run-20230404_203023-xcytp9ss\files\requirements.txt requirements.txt
2023-04-06 10:31:38 INFO scan save: D:\PycharmProjects\PPOimplementation\wandb\offline-run-20230404_203023-xcytp9ss\files\wandb-metadata.json wandb-metadata.json
2023-04-06 10:31:38 INFO scan save: D:\PycharmProjects\PPOimplementation\wandb\offline-run-20230404_203023-xcytp9ss\files\wandb-summary.json wandb-summary.json
2023-04-06 10:31:38 INFO scan save: D:\PycharmProjects\PPOimplementation\wandb\offline-run-20230404_203023-xcytp9ss\files\code\PPOmain.py code\PPOmain.py
2023-04-06 10:31:38 INFO send defer: 10
2023-04-06 10:31:38 INFO handle sender defer: 10
2023-04-06 10:31:38 INFO shutting down file pusher
2023-04-06 10:31:38 INFO shutting down sender
2023-04-06 10:31:38 INFO shutting down file pusher
2023-04-06 10:31:38 INFO waiting for file pusher
2023-04-06 10:31:39 INFO Uploaded file D:\PycharmProjects\PPOimplementation\wandb\offline-run-20230404_203023-xcytp9ss\files\config.yaml
2023-04-06 10:31:40 INFO Uploaded file D:\PycharmProjects\PPOimplementation\wandb\offline-run-20230404_203023-xcytp9ss\files\requirements.txt
2023-04-06 10:31:40 INFO Uploaded file D:\PycharmProjects\PPOimplementation\wandb\offline-run-20230404_203023-xcytp9ss\files\output.log
2023-04-06 10:31:40 INFO Uploaded file D:\PycharmProjects\PPOimplementation\wandb\offline-run-20230404_203023-xcytp9ss\files\wandb-summary.json
2023-04-06 10:31:43 INFO Uploaded file D:\PycharmProjects\PPOimplementation\wandb\offline-run-20230404_203023-xcytp9ss\files\conda-environment.yaml
2023-04-06 10:31:43 INFO send defer: 11
2023-04-06 15:23:12 WARNING Retrying (Retry(total=2, connect=None, read=None, redirect=None, status=None)) after connection broken by 'SSLError(SSLEOFError(8, 'EOF occurred in violation of protocol (_ssl.c:1131)'))': /api/5288891/envelope/
2023-04-06 15:23:12 WARNING Retrying (Retry(total=1, connect=None, read=None, redirect=None, status=None)) after connection broken by 'SSLError(SSLEOFError(8, 'EOF occurred in violation of protocol (_ssl.c:1131)'))': /api/5288891/envelope/
2023-04-06 15:23:12 WARNING Retrying (Retry(total=0, connect=None, read=None, redirect=None, status=None)) after connection broken by 'SSLError(SSLEOFError(8, 'EOF occurred in violation of protocol (_ssl.c:1131)'))': /api/5288891/envelope/
2023-04-06 19:08:46 WARNING Retrying (Retry(total=2, connect=None, read=None, redirect=None, status=None)) after connection broken by 'SSLError(SSLEOFError(8, 'EOF occurred in violation of protocol (_ssl.c:1131)'))': /api/5288891/envelope/
2023-04-06 19:08:46 WARNING Retrying (Retry(total=1, connect=None, read=None, redirect=None, status=None)) after connection broken by 'SSLError(SSLEOFError(8, 'EOF occurred in violation of protocol (_ssl.c:1131)'))': /api/5288891/envelope/
2023-04-06 19:08:46 WARNING Retrying (Retry(total=0, connect=None, read=None, redirect=None, status=None)) after connection broken by 'SSLError(SSLEOFError(8, 'EOF occurred in violation of protocol (_ssl.c:1131)'))': /api/5288891/envelope/
2023-04-06 20:24:33 WARNING Retrying (Retry(total=2, connect=None, read=None, redirect=None, status=None)) after connection broken by 'SSLError(SSLEOFError(8, 'EOF occurred in violation of protocol (_ssl.c:1131)'))': /api/5288891/envelope/
2023-04-06 20:24:33 WARNING Retrying (Retry(total=1, connect=None, read=None, redirect=None, status=None)) after connection broken by 'SSLError(SSLEOFError(8, 'EOF occurred in violation of protocol (_ssl.c:1131)'))': /api/5288891/envelope/
2023-04-06 20:24:33 WARNING Retrying (Retry(total=0, connect=None, read=None, redirect=None, status=None)) after connection broken by 'SSLError(SSLEOFError(8, 'EOF occurred in violation of protocol (_ssl.c:1131)'))': /api/5288891/envelope/
2023-04-06 20:33:24 WARNING Retrying (Retry(total=2, connect=None, read=None, redirect=None, status=None)) after connection broken by 'SSLError(SSLEOFError(8, 'EOF occurred in violation of protocol (_ssl.c:1131)'))': /api/5288891/envelope/
2023-04-06 20:33:24 WARNING Retrying (Retry(total=1, connect=None, read=None, redirect=None, status=None)) after connection broken by 'SSLError(SSLEOFError(8, 'EOF occurred in violation of protocol (_ssl.c:1131)'))': /api/5288891/envelope/
2023-04-06 20:33:24 WARNING Retrying (Retry(total=0, connect=None, read=None, redirect=None, status=None)) after connection broken by 'SSLError(SSLEOFError(8, 'EOF occurred in violation of protocol (_ssl.c:1131)'))': /api/5288891/envelope/
2023-04-11 13:58:13 WARNING Retrying (Retry(total=2, connect=None, read=None, redirect=None, status=None)) after connection broken by 'SSLError(SSLEOFError(8, 'EOF occurred in violation of protocol (_ssl.c:1131)'))': /api/5288891/envelope/
2023-04-11 13:58:13 WARNING Retrying (Retry(total=1, connect=None, read=None, redirect=None, status=None)) after connection broken by 'SSLError(SSLEOFError(8, 'EOF occurred in violation of protocol (_ssl.c:1131)'))': /api/5288891/envelope/
2023-04-11 13:58:13 WARNING Retrying (Retry(total=0, connect=None, read=None, redirect=None, status=None)) after connection broken by 'SSLError(SSLEOFError(8, 'EOF occurred in violation of protocol (_ssl.c:1131)'))': /api/5288891/envelope/
2023-04-11 16:12:51 WARNING Retrying (Retry(total=2, connect=None, read=None, redirect=None, status=None)) after connection broken by 'SSLError(SSLEOFError(8, 'EOF occurred in violation of protocol (_ssl.c:1131)'))': /api/5288891/envelope/
2023-04-11 16:12:51 WARNING Retrying (Retry(total=1, connect=None, read=None, redirect=None, status=None)) after connection broken by 'SSLError(SSLEOFError(8, 'EOF occurred in violation of protocol (_ssl.c:1131)'))': /api/5288891/envelope/
2023-04-11 16:12:51 WARNING Retrying (Retry(total=0, connect=None, read=None, redirect=None, status=None)) after connection broken by 'SSLError(SSLEOFError(8, 'EOF occurred in violation of protocol (_ssl.c:1131)'))': /api/5288891/envelope/
2023-04-12 10:34:34 WARNING Retrying (Retry(total=2, connect=None, read=None, redirect=None, status=None)) after connection broken by 'SSLError(SSLEOFError(8, 'EOF occurred in violation of protocol (_ssl.c:1131)'))': /api/5288891/envelope/
2023-04-12 10:34:34 WARNING Retrying (Retry(total=1, connect=None, read=None, redirect=None, status=None)) after connection broken by 'SSLError(SSLEOFError(8, 'EOF occurred in violation of protocol (_ssl.c:1131)'))': /api/5288891/envelope/
2023-04-12 10:34:34 WARNING Retrying (Retry(total=0, connect=None, read=None, redirect=None, status=None)) after connection broken by 'SSLError(SSLEOFError(8, 'EOF occurred in violation of protocol (_ssl.c:1131)'))': /api/5288891/envelope/
2023-04-12 20:07:27 WARNING Retrying (Retry(total=2, connect=None, read=None, redirect=None, status=None)) after connection broken by 'SSLError(SSLEOFError(8, 'EOF occurred in violation of protocol (_ssl.c:1131)'))': /api/5288891/envelope/
2023-04-12 20:07:27 WARNING Retrying (Retry(total=1, connect=None, read=None, redirect=None, status=None)) after connection broken by 'SSLError(SSLEOFError(8, 'EOF occurred in violation of protocol (_ssl.c:1131)'))': /api/5288891/envelope/
2023-04-12 20:07:27 WARNING Retrying (Retry(total=0, connect=None, read=None, redirect=None, status=None)) after connection broken by 'SSLError(SSLEOFError(8, 'EOF occurred in violation of protocol (_ssl.c:1131)'))': /api/5288891/envelope/
2023-04-12 20:31:31 WARNING Retrying (Retry(total=2, connect=None, read=None, redirect=None, status=None)) after connection broken by 'SSLError(SSLEOFError(8, 'EOF occurred in violation of protocol (_ssl.c:1131)'))': /api/5288891/envelope/
2023-04-12 20:31:31 WARNING Retrying (Retry(total=1, connect=None, read=None, redirect=None, status=None)) after connection broken by 'SSLError(SSLEOFError(8, 'EOF occurred in violation of protocol (_ssl.c:1131)'))': /api/5288891/envelope/
2023-04-12 20:31:31 WARNING Retrying (Retry(total=0, connect=None, read=None, redirect=None, status=None)) after connection broken by 'SSLError(SSLEOFError(8, 'EOF occurred in violation of protocol (_ssl.c:1131)'))': /api/5288891/envelope/
2023-04-12 20:43:34 WARNING Retrying (Retry(total=2, connect=None, read=None, redirect=None, status=None)) after connection broken by 'SSLError(SSLEOFError(8, 'EOF occurred in violation of protocol (_ssl.c:1131)'))': /api/5288891/envelope/
2023-04-12 20:43:34 WARNING Retrying (Retry(total=1, connect=None, read=None, redirect=None, status=None)) after connection broken by 'SSLError(SSLEOFError(8, 'EOF occurred in violation of protocol (_ssl.c:1131)'))': /api/5288891/envelope/
2023-04-12 20:43:34 WARNING Retrying (Retry(total=0, connect=None, read=None, redirect=None, status=None)) after connection broken by 'SSLError(SSLEOFError(8, 'EOF occurred in violation of protocol (_ssl.c:1131)'))': /api/5288891/envelope/
2023-04-12 22:13:36 WARNING Retrying (Retry(total=2, connect=None, read=None, redirect=None, status=None)) after connection broken by 'SSLError(SSLEOFError(8, 'EOF occurred in violation of protocol (_ssl.c:1131)'))': /api/5288891/envelope/
2023-04-12 22:13:36 WARNING Retrying (Retry(total=1, connect=None, read=None, redirect=None, status=None)) after connection broken by 'SSLError(SSLEOFError(8, 'EOF occurred in violation of protocol (_ssl.c:1131)'))': /api/5288891/envelope/
2023-04-12 22:13:36 WARNING Retrying (Retry(total=0, connect=None, read=None, redirect=None, status=None)) after connection broken by 'SSLError(SSLEOFError(8, 'EOF occurred in violation of protocol (_ssl.c:1131)'))': /api/5288891/envelope/
2023-04-12 22:33:28 WARNING Retrying (Retry(total=2, connect=None, read=None, redirect=None, status=None)) after connection broken by 'SSLError(SSLEOFError(8, 'EOF occurred in violation of protocol (_ssl.c:1131)'))': /api/5288891/envelope/
2023-04-12 22:33:28 WARNING Retrying (Retry(total=1, connect=None, read=None, redirect=None, status=None)) after connection broken by 'SSLError(SSLEOFError(8, 'EOF occurred in violation of protocol (_ssl.c:1131)'))': /api/5288891/envelope/
2023-04-12 22:33:28 WARNING Retrying (Retry(total=0, connect=None, read=None, redirect=None, status=None)) after connection broken by 'SSLError(SSLEOFError(8, 'EOF occurred in violation of protocol (_ssl.c:1131)'))': /api/5288891/envelope/
2023-04-13 10:37:39 WARNING Retrying (Retry(total=2, connect=None, read=None, redirect=None, status=None)) after connection broken by 'SSLError(SSLEOFError(8, 'EOF occurred in violation of protocol (_ssl.c:1131)'))': /api/5288891/envelope/
2023-04-13 10:37:39 WARNING Retrying (Retry(total=1, connect=None, read=None, redirect=None, status=None)) after connection broken by 'SSLError(SSLEOFError(8, 'EOF occurred in violation of protocol (_ssl.c:1131)'))': /api/5288891/envelope/
2023-04-13 10:37:39 WARNING Retrying (Retry(total=0, connect=None, read=None, redirect=None, status=None)) after connection broken by 'SSLError(SSLEOFError(8, 'EOF occurred in violation of protocol (_ssl.c:1131)'))': /api/5288891/envelope/
2023-04-13 20:27:44 WARNING Retrying (Retry(total=2, connect=None, read=None, redirect=None, status=None)) after connection broken by 'SSLError(SSLEOFError(8, 'EOF occurred in violation of protocol (_ssl.c:1131)'))': /api/5288891/envelope/
2023-04-13 20:27:44 WARNING Retrying (Retry(total=1, connect=None, read=None, redirect=None, status=None)) after connection broken by 'SSLError(SSLEOFError(8, 'EOF occurred in violation of protocol (_ssl.c:1131)'))': /api/5288891/envelope/
2023-04-13 20:27:44 WARNING Retrying (Retry(total=0, connect=None, read=None, redirect=None, status=None)) after connection broken by 'SSLError(SSLEOFError(8, 'EOF occurred in violation of protocol (_ssl.c:1131)'))': /api/5288891/envelope/
2023-04-14 16:32:28 WARNING Retrying (Retry(total=2, connect=None, read=None, redirect=None, status=None)) after connection broken by 'SSLError(SSLEOFError(8, 'EOF occurred in violation of protocol (_ssl.c:1131)'))': /api/5288891/envelope/
2023-04-14 16:32:28 WARNING Retrying (Retry(total=1, connect=None, read=None, redirect=None, status=None)) after connection broken by 'SSLError(SSLEOFError(8, 'EOF occurred in violation of protocol (_ssl.c:1131)'))': /api/5288891/envelope/
2023-04-14 16:32:28 WARNING Retrying (Retry(total=0, connect=None, read=None, redirect=None, status=None)) after connection broken by 'SSLError(SSLEOFError(8, 'EOF occurred in violation of protocol (_ssl.c:1131)'))': /api/5288891/envelope/
2023-04-15 15:06:56 WARNING Retrying (Retry(total=2, connect=None, read=None, redirect=None, status=None)) after connection broken by 'SSLError(SSLEOFError(8, 'EOF occurred in violation of protocol (_ssl.c:1131)'))': /api/5288891/envelope/
2023-04-15 15:06:56 WARNING Retrying (Retry(total=1, connect=None, read=None, redirect=None, status=None)) after connection broken by 'SSLError(SSLEOFError(8, 'EOF occurred in violation of protocol (_ssl.c:1131)'))': /api/5288891/envelope/
2023-04-15 15:06:56 WARNING Retrying (Retry(total=0, connect=None, read=None, redirect=None, status=None)) after connection broken by 'SSLError(SSLEOFError(8, 'EOF occurred in violation of protocol (_ssl.c:1131)'))': /api/5288891/envelope/
2023-04-17 21:40:22 WARNING Retrying (Retry(total=2, connect=None, read=None, redirect=None, status=None)) after connection broken by 'SSLError(SSLEOFError(8, 'EOF occurred in violation of protocol (_ssl.c:1131)'))': /api/5288891/envelope/
2023-04-17 21:40:22 WARNING Retrying (Retry(total=1, connect=None, read=None, redirect=None, status=None)) after connection broken by 'SSLError(SSLEOFError(8, 'EOF occurred in violation of protocol (_ssl.c:1131)'))': /api/5288891/envelope/
2023-04-17 21:40:22 WARNING Retrying (Retry(total=0, connect=None, read=None, redirect=None, status=None)) after connection broken by 'SSLError(SSLEOFError(8, 'EOF occurred in violation of protocol (_ssl.c:1131)'))': /api/5288891/envelope/
2023-04-19 21:40:57 WARNING Retrying (Retry(total=2, connect=None, read=None, redirect=None, status=None)) after connection broken by 'SSLError(SSLEOFError(8, 'EOF occurred in violation of protocol (_ssl.c:1131)'))': /api/5288891/envelope/
2023-04-19 21:40:57 WARNING Retrying (Retry(total=1, connect=None, read=None, redirect=None, status=None)) after connection broken by 'SSLError(SSLEOFError(8, 'EOF occurred in violation of protocol (_ssl.c:1131)'))': /api/5288891/envelope/
2023-04-19 21:40:57 WARNING Retrying (Retry(total=0, connect=None, read=None, redirect=None, status=None)) after connection broken by 'SSLError(SSLEOFError(8, 'EOF occurred in violation of protocol (_ssl.c:1131)'))': /api/5288891/envelope/
2023-04-20 10:39:44 WARNING Retrying (Retry(total=2, connect=None, read=None, redirect=None, status=None)) after connection broken by 'SSLError(SSLEOFError(8, 'EOF occurred in violation of protocol (_ssl.c:1131)'))': /api/5288891/envelope/
2023-04-20 10:39:44 WARNING Retrying (Retry(total=1, connect=None, read=None, redirect=None, status=None)) after connection broken by 'SSLError(SSLEOFError(8, 'EOF occurred in violation of protocol (_ssl.c:1131)'))': /api/5288891/envelope/
2023-04-20 10:39:44 WARNING Retrying (Retry(total=0, connect=None, read=None, redirect=None, status=None)) after connection broken by 'SSLError(SSLEOFError(8, 'EOF occurred in violation of protocol (_ssl.c:1131)'))': /api/5288891/envelope/
2023-04-20 10:58:18 WARNING Retrying (Retry(total=2, connect=None, read=None, redirect=None, status=None)) after connection broken by 'SSLError(SSLEOFError(8, 'EOF occurred in violation of protocol (_ssl.c:1131)'))': /api/5288891/envelope/
2023-04-20 10:58:18 WARNING Retrying (Retry(total=1, connect=None, read=None, redirect=None, status=None)) after connection broken by 'SSLError(SSLEOFError(8, 'EOF occurred in violation of protocol (_ssl.c:1131)'))': /api/5288891/envelope/
2023-04-20 10:58:18 WARNING Retrying (Retry(total=0, connect=None, read=None, redirect=None, status=None)) after connection broken by 'SSLError(SSLEOFError(8, 'EOF occurred in violation of protocol (_ssl.c:1131)'))': /api/5288891/envelope/
2023-04-20 14:35:05 WARNING Retrying (Retry(total=2, connect=None, read=None, redirect=None, status=None)) after connection broken by 'SSLError(SSLEOFError(8, 'EOF occurred in violation of protocol (_ssl.c:1131)'))': /api/5288891/envelope/
2023-04-20 14:35:05 WARNING Retrying (Retry(total=1, connect=None, read=None, redirect=None, status=None)) after connection broken by 'SSLError(SSLEOFError(8, 'EOF occurred in violation of protocol (_ssl.c:1131)'))': /api/5288891/envelope/
2023-04-20 14:35:05 WARNING Retrying (Retry(total=0, connect=None, read=None, redirect=None, status=None)) after connection broken by 'SSLError(SSLEOFError(8, 'EOF occurred in violation of protocol (_ssl.c:1131)'))': /api/5288891/envelope/
2023-04-20 15:03:12 WARNING Retrying (Retry(total=2, connect=None, read=None, redirect=None, status=None)) after connection broken by 'SSLError(SSLEOFError(8, 'EOF occurred in violation of protocol (_ssl.c:1131)'))': /api/5288891/envelope/
2023-04-20 15:03:12 WARNING Retrying (Retry(total=1, connect=None, read=None, redirect=None, status=None)) after connection broken by 'SSLError(SSLEOFError(8, 'EOF occurred in violation of protocol (_ssl.c:1131)'))': /api/5288891/envelope/
2023-04-20 15:03:12 WARNING Retrying (Retry(total=0, connect=None, read=None, redirect=None, status=None)) after connection broken by 'SSLError(SSLEOFError(8, 'EOF occurred in violation of protocol (_ssl.c:1131)'))': /api/5288891/envelope/
2023-04-20 15:33:05 WARNING Retrying (Retry(total=2, connect=None, read=None, redirect=None, status=None)) after connection broken by 'SSLError(SSLEOFError(8, 'EOF occurred in violation of protocol (_ssl.c:1131)'))': /api/5288891/envelope/
2023-04-20 15:33:05 WARNING Retrying (Retry(total=1, connect=None, read=None, redirect=None, status=None)) after connection broken by 'SSLError(SSLEOFError(8, 'EOF occurred in violation of protocol (_ssl.c:1131)'))': /api/5288891/envelope/
2023-04-20 15:33:05 WARNING Retrying (Retry(total=0, connect=None, read=None, redirect=None, status=None)) after connection broken by 'SSLError(SSLEOFError(8, 'EOF occurred in violation of protocol (_ssl.c:1131)'))': /api/5288891/envelope/
2023-04-20 16:25:09 WARNING Retrying (Retry(total=2, connect=None, read=None, redirect=None, status=None)) after connection broken by 'SSLError(SSLEOFError(8, 'EOF occurred in violation of protocol (_ssl.c:1131)'))': /api/5288891/envelope/
2023-04-20 16:25:09 WARNING Retrying (Retry(total=1, connect=None, read=None, redirect=None, status=None)) after connection broken by 'SSLError(SSLEOFError(8, 'EOF occurred in violation of protocol (_ssl.c:1131)'))': /api/5288891/envelope/
2023-04-20 16:25:09 WARNING Retrying (Retry(total=0, connect=None, read=None, redirect=None, status=None)) after connection broken by 'SSLError(SSLEOFError(8, 'EOF occurred in violation of protocol (_ssl.c:1131)'))': /api/5288891/envelope/
2023-04-20 20:12:18 WARNING Retrying (Retry(total=2, connect=None, read=None, redirect=None, status=None)) after connection broken by 'SSLError(SSLEOFError(8, 'EOF occurred in violation of protocol (_ssl.c:1131)'))': /api/5288891/envelope/
2023-04-20 20:12:18 WARNING Retrying (Retry(total=1, connect=None, read=None, redirect=None, status=None)) after connection broken by 'SSLError(SSLEOFError(8, 'EOF occurred in violation of protocol (_ssl.c:1131)'))': /api/5288891/envelope/
2023-04-20 20:12:18 WARNING Retrying (Retry(total=0, connect=None, read=None, redirect=None, status=None)) after connection broken by 'SSLError(SSLEOFError(8, 'EOF occurred in violation of protocol (_ssl.c:1131)'))': /api/5288891/envelope/
2023-04-21 14:02:23 WARNING Retrying (Retry(total=2, connect=None, read=None, redirect=None, status=None)) after connection broken by 'SSLError(SSLEOFError(8, 'EOF occurred in violation of protocol (_ssl.c:1131)'))': /api/5288891/envelope/
2023-04-21 14:02:23 WARNING Retrying (Retry(total=1, connect=None, read=None, redirect=None, status=None)) after connection broken by 'SSLError(SSLEOFError(8, 'EOF occurred in violation of protocol (_ssl.c:1131)'))': /api/5288891/envelope/
2023-04-21 14:02:23 WARNING Retrying (Retry(total=0, connect=None, read=None, redirect=None, status=None)) after connection broken by 'SSLError(SSLEOFError(8, 'EOF occurred in violation of protocol (_ssl.c:1131)'))': /api/5288891/envelope/
2023-04-22 17:12:01 WARNING Retrying (Retry(total=2, connect=None, read=None, redirect=None, status=None)) after connection broken by 'SSLError(SSLEOFError(8, 'EOF occurred in violation of protocol (_ssl.c:1131)'))': /api/5288891/envelope/
2023-04-22 17:12:01 WARNING Retrying (Retry(total=1, connect=None, read=None, redirect=None, status=None)) after connection broken by 'SSLError(SSLEOFError(8, 'EOF occurred in violation of protocol (_ssl.c:1131)'))': /api/5288891/envelope/
2023-04-22 17:12:01 WARNING Retrying (Retry(total=0, connect=None, read=None, redirect=None, status=None)) after connection broken by 'SSLError(SSLEOFError(8, 'EOF occurred in violation of protocol (_ssl.c:1131)'))': /api/5288891/envelope/
2023-04-22 17:34:46 WARNING Retrying (Retry(total=2, connect=None, read=None, redirect=None, status=None)) after connection broken by 'SSLError(SSLEOFError(8, 'EOF occurred in violation of protocol (_ssl.c:1131)'))': /api/5288891/envelope/
2023-04-22 17:34:46 WARNING Retrying (Retry(total=1, connect=None, read=None, redirect=None, status=None)) after connection broken by 'SSLError(SSLEOFError(8, 'EOF occurred in violation of protocol (_ssl.c:1131)'))': /api/5288891/envelope/
2023-04-22 17:34:46 WARNING Retrying (Retry(total=0, connect=None, read=None, redirect=None, status=None)) after connection broken by 'SSLError(SSLEOFError(8, 'EOF occurred in violation of protocol (_ssl.c:1131)'))': /api/5288891/envelope/
2023-04-22 17:38:19 WARNING Retrying (Retry(total=2, connect=None, read=None, redirect=None, status=None)) after connection broken by 'SSLError(SSLEOFError(8, 'EOF occurred in violation of protocol (_ssl.c:1131)'))': /api/5288891/envelope/
2023-04-22 17:38:19 WARNING Retrying (Retry(total=1, connect=None, read=None, redirect=None, status=None)) after connection broken by 'SSLError(SSLEOFError(8, 'EOF occurred in violation of protocol (_ssl.c:1131)'))': /api/5288891/envelope/
2023-04-22 17:38:19 WARNING Retrying (Retry(total=0, connect=None, read=None, redirect=None, status=None)) after connection broken by 'SSLError(SSLEOFError(8, 'EOF occurred in violation of protocol (_ssl.c:1131)'))': /api/5288891/envelope/
2023-04-22 17:56:21 WARNING Retrying (Retry(total=2, connect=None, read=None, redirect=None, status=None)) after connection broken by 'SSLError(SSLEOFError(8, 'EOF occurred in violation of protocol (_ssl.c:1131)'))': /api/5288891/envelope/
2023-04-22 17:56:21 WARNING Retrying (Retry(total=1, connect=None, read=None, redirect=None, status=None)) after connection broken by 'SSLError(SSLEOFError(8, 'EOF occurred in violation of protocol (_ssl.c:1131)'))': /api/5288891/envelope/
2023-04-22 17:56:21 WARNING Retrying (Retry(total=0, connect=None, read=None, redirect=None, status=None)) after connection broken by 'SSLError(SSLEOFError(8, 'EOF occurred in violation of protocol (_ssl.c:1131)'))': /api/5288891/envelope/
2023-04-22 18:02:30 WARNING Retrying (Retry(total=2, connect=None, read=None, redirect=None, status=None)) after connection broken by 'SSLError(SSLEOFError(8, 'EOF occurred in violation of protocol (_ssl.c:1131)'))': /api/5288891/envelope/
2023-04-22 18:02:30 WARNING Retrying (Retry(total=1, connect=None, read=None, redirect=None, status=None)) after connection broken by 'SSLError(SSLEOFError(8, 'EOF occurred in violation of protocol (_ssl.c:1131)'))': /api/5288891/envelope/
2023-04-22 18:02:30 WARNING Retrying (Retry(total=0, connect=None, read=None, redirect=None, status=None)) after connection broken by 'SSLError(SSLEOFError(8, 'EOF occurred in violation of protocol (_ssl.c:1131)'))': /api/5288891/envelope/
2023-04-23 20:42:39 WARNING Retrying (Retry(total=2, connect=None, read=None, redirect=None, status=None)) after connection broken by 'SSLError(SSLEOFError(8, 'EOF occurred in violation of protocol (_ssl.c:1131)'))': /api/5288891/envelope/
2023-04-23 20:42:39 WARNING Retrying (Retry(total=1, connect=None, read=None, redirect=None, status=None)) after connection broken by 'SSLError(SSLEOFError(8, 'EOF occurred in violation of protocol (_ssl.c:1131)'))': /api/5288891/envelope/
2023-04-23 20:42:39 WARNING Retrying (Retry(total=0, connect=None, read=None, redirect=None, status=None)) after connection broken by 'SSLError(SSLEOFError(8, 'EOF occurred in violation of protocol (_ssl.c:1131)'))': /api/5288891/envelope/
2023-04-24 14:47:56 WARNING Retrying (Retry(total=2, connect=None, read=None, redirect=None, status=None)) after connection broken by 'SSLError(SSLEOFError(8, 'EOF occurred in violation of protocol (_ssl.c:1131)'))': /api/5288891/envelope/
2023-04-24 14:47:56 WARNING Retrying (Retry(total=1, connect=None, read=None, redirect=None, status=None)) after connection broken by 'SSLError(SSLEOFError(8, 'EOF occurred in violation of protocol (_ssl.c:1131)'))': /api/5288891/envelope/
2023-04-24 14:47:56 WARNING Retrying (Retry(total=0, connect=None, read=None, redirect=None, status=None)) after connection broken by 'SSLError(SSLEOFError(8, 'EOF occurred in violation of protocol (_ssl.c:1131)'))': /api/5288891/envelope/
2023-04-25 18:44:09 WARNING Retrying (Retry(total=2, connect=None, read=None, redirect=None, status=None)) after connection broken by 'SSLError(SSLEOFError(8, 'EOF occurred in violation of protocol (_ssl.c:1131)'))': /api/5288891/envelope/
2023-04-25 18:44:09 WARNING Retrying (Retry(total=1, connect=None, read=None, redirect=None, status=None)) after connection broken by 'SSLError(SSLEOFError(8, 'EOF occurred in violation of protocol (_ssl.c:1131)'))': /api/5288891/envelope/
2023-04-25 18:44:09 WARNING Retrying (Retry(total=0, connect=None, read=None, redirect=None, status=None)) after connection broken by 'SSLError(SSLEOFError(8, 'EOF occurred in violation of protocol (_ssl.c:1131)'))': /api/5288891/envelope/
