2023-04-06 14:57:21,665 INFO    MainThread:2944 [wandb_setup.py:_flush():76] Configure stats pid to 2944
2023-04-06 14:57:21,665 INFO    MainThread:2944 [wandb_setup.py:_flush():76] Loading settings from C:\Users\JinLab\.config\wandb\settings
2023-04-06 14:57:21,665 INFO    MainThread:2944 [wandb_setup.py:_flush():76] Loading settings from D:\PycharmProjects\PPOimplementation\wandb\settings
2023-04-06 14:57:21,665 INFO    MainThread:2944 [wandb_setup.py:_flush():76] Loading settings from environment variables: {}
2023-04-06 14:57:21,665 INFO    MainThread:2944 [wandb_setup.py:_flush():76] Applying setup settings: {'_disable_service': False}
2023-04-06 14:57:21,665 INFO    MainThread:2944 [wandb_setup.py:_flush():76] Inferring run settings from compute environment: {'program_relpath': 'PPOmain.py', 'program': 'PPOmain.py'}
2023-04-06 14:57:21,666 INFO    MainThread:2944 [wandb_init.py:_log_setup():506] Logging user logs to D:\PycharmProjects\PPOimplementation\wandb\run-20230406_145721-q6uaomak\logs\debug.log
2023-04-06 14:57:21,666 INFO    MainThread:2944 [wandb_init.py:_log_setup():507] Logging internal logs to D:\PycharmProjects\PPOimplementation\wandb\run-20230406_145721-q6uaomak\logs\debug-internal.log
2023-04-06 14:57:21,666 INFO    MainThread:2944 [wandb_init.py:init():546] calling init triggers
2023-04-06 14:57:21,667 INFO    MainThread:2944 [wandb_init.py:init():552] wandb.init called with sweep_config: {}
config: {'exp_name': 'PPOmain', 'seed': 1, 'torch_deterministic': True, 'track': True, 'wandb_project_name': 'PPO_implementation', 'wandb_entity': 'Aramiis', 'policy_dist': 'Beta', 'env_id': 'gym_STAR/My_Env-v1', 'max_train_steps': 3000000.0, 'evaluate_freq': 5000.0, 'lr_a': 0.0003, 'lr_c': 0.0003, 'batch_size': 2048, 'minibatch_size': 64, 'update_epochs': 10, 'gamma': 0.99, 'lamda': 0.95, 'epsilon': 0.2, 'entropy_coef': 0.01, 'valuef_coef': 0.5, 'batch_adv_norm': True, 'mbatch_adv_norm': False, 'vloss_clip': True, 'use_state_norm': True, 'hidden_width': 64, 'state_dim': 554, 'action_dim': 126, 'max_action': 1.0}
2023-04-06 14:57:21,667 INFO    MainThread:2944 [wandb_init.py:init():602] starting backend
2023-04-06 14:57:21,667 INFO    MainThread:2944 [wandb_init.py:init():606] setting up manager
2023-04-06 14:57:21,683 INFO    MainThread:2944 [wandb_init.py:init():613] backend started and connected
2023-04-06 14:57:21,703 INFO    MainThread:2944 [wandb_init.py:init():701] updated telemetry
2023-04-06 14:57:21,776 INFO    MainThread:2944 [wandb_init.py:init():741] communicating run to backend with 60.0 second timeout
2023-04-06 14:57:51,700 INFO    Thread-7  :2944 [retry.py:__call__():172] Retry attempt failed:
Traceback (most recent call last):
  File "D:\anaconda3\envs\STAR_DEPLOY\lib\site-packages\urllib3\connectionpool.py", line 449, in _make_request
    six.raise_from(e, None)
  File "<string>", line 3, in raise_from
  File "D:\anaconda3\envs\STAR_DEPLOY\lib\site-packages\urllib3\connectionpool.py", line 444, in _make_request
    httplib_response = conn.getresponse()
  File "D:\anaconda3\envs\STAR_DEPLOY\lib\http\client.py", line 1348, in getresponse
    response.begin()
  File "D:\anaconda3\envs\STAR_DEPLOY\lib\http\client.py", line 316, in begin
    version, status, reason = self._read_status()
  File "D:\anaconda3\envs\STAR_DEPLOY\lib\http\client.py", line 277, in _read_status
    line = str(self.fp.readline(_MAXLINE + 1), "iso-8859-1")
  File "D:\anaconda3\envs\STAR_DEPLOY\lib\socket.py", line 669, in readinto
    return self._sock.recv_into(b)
  File "D:\anaconda3\envs\STAR_DEPLOY\lib\ssl.py", line 1241, in recv_into
    return self.read(nbytes, buffer)
  File "D:\anaconda3\envs\STAR_DEPLOY\lib\ssl.py", line 1099, in read
    return self._sslobj.read(len, buffer)
socket.timeout: The read operation timed out

During handling of the above exception, another exception occurred:

Traceback (most recent call last):
  File "D:\anaconda3\envs\STAR_DEPLOY\lib\site-packages\requests\adapters.py", line 489, in send
    resp = conn.urlopen(
  File "D:\anaconda3\envs\STAR_DEPLOY\lib\site-packages\urllib3\connectionpool.py", line 787, in urlopen
    retries = retries.increment(
  File "D:\anaconda3\envs\STAR_DEPLOY\lib\site-packages\urllib3\util\retry.py", line 550, in increment
    raise six.reraise(type(error), error, _stacktrace)
  File "D:\anaconda3\envs\STAR_DEPLOY\lib\site-packages\urllib3\packages\six.py", line 770, in reraise
    raise value
  File "D:\anaconda3\envs\STAR_DEPLOY\lib\site-packages\urllib3\connectionpool.py", line 703, in urlopen
    httplib_response = self._make_request(
  File "D:\anaconda3\envs\STAR_DEPLOY\lib\site-packages\urllib3\connectionpool.py", line 451, in _make_request
    self._raise_timeout(err=e, url=url, timeout_value=read_timeout)
  File "D:\anaconda3\envs\STAR_DEPLOY\lib\site-packages\urllib3\connectionpool.py", line 340, in _raise_timeout
    raise ReadTimeoutError(
urllib3.exceptions.ReadTimeoutError: HTTPSConnectionPool(host='api.wandb.ai', port=443): Read timed out. (read timeout=10)

During handling of the above exception, another exception occurred:

Traceback (most recent call last):
  File "D:\anaconda3\envs\STAR_DEPLOY\lib\site-packages\wandb\sdk\lib\retry.py", line 131, in __call__
    result = self._call_fn(*args, **kwargs)
  File "D:\anaconda3\envs\STAR_DEPLOY\lib\site-packages\wandb\sdk\internal\internal_api.py", line 243, in execute
    return self.client.execute(*args, **kwargs)  # type: ignore
  File "D:\anaconda3\envs\STAR_DEPLOY\lib\site-packages\wandb\vendor\gql-0.2.0\wandb_gql\client.py", line 52, in execute
    result = self._get_result(document, *args, **kwargs)
  File "D:\anaconda3\envs\STAR_DEPLOY\lib\site-packages\wandb\vendor\gql-0.2.0\wandb_gql\client.py", line 60, in _get_result
    return self.transport.execute(document, *args, **kwargs)
  File "D:\anaconda3\envs\STAR_DEPLOY\lib\site-packages\wandb\vendor\gql-0.2.0\wandb_gql\transport\requests.py", line 38, in execute
    request = requests.post(self.url, **post_args)
  File "D:\anaconda3\envs\STAR_DEPLOY\lib\site-packages\requests\api.py", line 115, in post
    return request("post", url, data=data, json=json, **kwargs)
  File "D:\anaconda3\envs\STAR_DEPLOY\lib\site-packages\requests\api.py", line 59, in request
    return session.request(method=method, url=url, **kwargs)
  File "D:\anaconda3\envs\STAR_DEPLOY\lib\site-packages\requests\sessions.py", line 587, in request
    resp = self.send(prep, **send_kwargs)
  File "D:\anaconda3\envs\STAR_DEPLOY\lib\site-packages\requests\sessions.py", line 701, in send
    r = adapter.send(request, **kwargs)
  File "D:\anaconda3\envs\STAR_DEPLOY\lib\site-packages\requests\adapters.py", line 578, in send
    raise ReadTimeout(e, request=request)
requests.exceptions.ReadTimeout: HTTPSConnectionPool(host='api.wandb.ai', port=443): Read timed out. (read timeout=10)
2023-04-06 14:58:22,422 ERROR   MainThread:2944 [wandb_init.py:init():755] backend process timed out, exiting...
encountered error: Error communicating with wandb process, exiting...
For more info see: https://docs.wandb.ai/guides/track/tracking-faq#initstarterror-error-communicating-with-wandb-process-
2023-04-06 14:58:22,440 ERROR   MainThread:2944 [wandb_init.py:init():1171] error
Traceback (most recent call last):
  File "D:\anaconda3\envs\STAR_DEPLOY\lib\site-packages\wandb\sdk\wandb_init.py", line 1144, in init
    run = wi.init()
  File "D:\anaconda3\envs\STAR_DEPLOY\lib\site-packages\wandb\sdk\wandb_init.py", line 773, in init
    raise error
wandb.errors.CommError: Error communicating with wandb process, exiting...
For more info see: https://docs.wandb.ai/guides/track/tracking-faq#initstarterror-error-communicating-with-wandb-process-
